<?xml version="1.0"?>
<robot name="pr2"
       xmlns:xi="http://www.w3.org/2001/XInclude"
       xmlns:gazebo="http://playerstage.sourceforge.net/gazebo/xmlschema/#gz"
       xmlns:model="http://playerstage.sourceforge.net/gazebo/xmlschema/#model"
       xmlns:sensor="http://playerstage.sourceforge.net/gazebo/xmlschema/#sensor"
       xmlns:body="http://playerstage.sourceforge.net/gazebo/xmlschema/#body"
       xmlns:geom="http://playerstage.sourceforge.net/gazebo/xmlschema/#geom"
       xmlns:joint="http://playerstage.sourceforge.net/gazebo/xmlschema/#joint"
       xmlns:interface="http://playerstage.sourceforge.net/gazebo/xmlschema/#interface"
       xmlns:rendering="http://playerstage.sourceforge.net/gazebo/xmlschema/#rendering"
       xmlns:renderable="http://playerstage.sourceforge.net/gazebo/xmlschema/#renderable"
       xmlns:controller="http://playerstage.sourceforge.net/gazebo/xmlschema/#controller"
       xmlns:physics="http://playerstage.sourceforge.net/gazebo/xmlschema/#physics">

  <property name="M_PI" value="3.1415926535897931" />

  <property name="wall_x_loc" value="1.25" />
  <property name="handle_height" value="0.87" />
  <property name="jack_offset_y" value="0.02315" />
  <property name="jack_offset_z" value="0.01935" />
  <property name="outlet_height" value="0.3" />
  <property name="outlet_size_w" value="0.11431" />
  <property name="outlet_size_h" value="0.11567" />
  <property name="jack_width"    value="0.033" />
  <property name="jack_height"   value="0.028" />

  <joint name="floor_joint" type="planar" > 
    <parent link="world" />
    <origin xyz="${wall_x_loc} 0.0 0.01" rpy="0 0 0" />
    <child link="floor_link" />
  </joint>
  <!-- link blocks -->
  <link name="floor_link">
    <inertial>
      <mass value="100" />
      <com xyz="4 0 0.001" />
      <inertia ixx="10" ixy="0"  ixz="0"
               iyy="10" iyz="0"
               izz="10" />
    </inertial> 
    <visual>
      <origin xyz="4 0 0.001" rpy="0 0 0" />
      <geometry name="floor_visual_geom">
        <box size="8 8 0.002" />
      </geometry>
    </visual> 
    <collision>
      <origin xyz="4 0 0.001" rpy="0.0 0.0 0.0" />
      <geometry name="floor_collision_geom">
        <box size="8 8 0.002" />
      </geometry>
    </collision>
  </link>
  <gazebo reference="floor_link">
    <material>Gazebo/Grey</material>
    <mu1>50.0</mu1>
    <mu2>50.0</mu2>
    <kp>100000000.0</kp>
    <kd>1.0</kd>
  </gazebo>

  <joint name="wall_joint" type="fixed" >
    <parent link="floor_link" />
    <origin xyz="0 0 1" rpy="0 0 0" />
    <child link="wall_link" />
  </joint>
  <link name="wall_link">
    <inertial>
      <mass value="100" />
      <com xyz="0 0 1" />
      <inertia ixx="10" ixy="0"  ixz="0"
               iyy="10" iyz="0"
               izz="10" />
    </inertial> 
    <visual>
      <origin xyz="0 0 0" rpy="0 0 0" />
      <geometry name="wall_visual_geom">
        <box size="0.4 10 2" />
      </geometry>
    </visual> 
    <collision>
      <origin xyz="0 0 0" rpy="0.0 0.0 0.0" />
      <geometry name="wall_collision_geom">
        <box size="0.4 10 2" />
      </geometry>
    </collision>
  </link>

  <gazebo reference="wall_link">
    <material>PR2/Yellow</material>
    <laserRetro>0.5</laserRetro>
    <selfCollide>true</selfCollide>
  </gazebo>

  
  <joint name="outlet_joint" type="fixed" >
    <parent link="wall_link" />
    <origin xyz="-0.20 0.0 ${-1.0+outlet_height}" rpy="0 0 0" />
    <child link="outlet_link" />
  </joint>
  <link name="outlet_link">
    <inertial >
      <mass value="1" />
      <com xyz="0.0 0.0 0.0" /> 
      <inertia  ixx="0.1" ixy="0.0"  ixz="0.0"
                iyy="0.1" iyz="0.0"
                izz="0.1" />
    </inertial>
    <visual >
      <origin xyz="0.0 0.0 0.0" rpy="0 0 0" />
      <geometry name="outlet_visual">
        <box size="0.01 ${outlet_size_w} ${outlet_size_h}" />
      </geometry>
    </visual>
    <collision >
      <origin xyz="0.0 0.0 0.0" rpy="0 0 0" />
      <geometry name="outlet_collision_geom">
        <box size="0.01 ${outlet_size_w} ${outlet_size_h}" />
      </geometry>
    </collision>
  </link>
  <gazebo reference="outlet_link">
    <material>PR2/Outlet</material>
    <laserRetro>10.0</laserRetro>
    <turnGravityOff>true</turnGravityOff>
    <selfCollide>true</selfCollide>
  </gazebo>

  <!--
  <joint name="jack1_joint" type="fixed" >
    <parent link="outlet_link" />
    <origin xyz="-0.006 ${-jack_offset_y} ${-jack_offset_z}" rpy="0 0 0" />
    <child link="jack1_link" />
  </joint>
  <link name="jack1_link">
    <inertial >
      <mass value="1.0" />
      <com xyz="0.0 0.0 0.0" /> 
      <inertia  ixx="0.1" ixy="0.0"  ixz="0.0"
                iyy="0.1" iyz="0.0"
                izz="0.1" />
    </inertial>
    <visual >
      <origin xyz="0.0 0.0 0.0" rpy="0 0 0" />
      <geometry name="jack1_visual">
        <box size="0.01 ${jack_width} ${jack_height}" />
      </geometry>
    </visual>
    <collision >
      <origin xyz="0.0 0.0 0.0" rpy="0 0 0" />
      <geometry name="jack1_collision_geom">
        <box size="0.01 ${jack_width} ${jack_height}" />
      </geometry>
    </collision>
  </link>
  <gazebo reference="jack1_link">
    <material>PR2/Jack</material>
    <laserRetro>10.0</laserRetro>
    <turnGravityOff>true</turnGravityOff>
    <selfCollide>true</selfCollide>
  </gazebo>

  <joint name="jack2_joint" type="fixed" >
    <parent link="outlet_link" />
    <origin xyz="-0.006 ${ jack_offset_y} ${-jack_offset_z}" rpy="0 0 0" />
    <child link="jack2_link" />
  </joint>
  <link name="jack2_link">
    <inertial >
      <mass value="1.0" />
      <com xyz="0.0 0.0 0.0" /> 
      <inertia  ixx="0.1" ixy="0.0"  ixz="0.0"
                iyy="0.1" iyz="0.0"
                izz="0.1" />
    </inertial>
    <visual >
      <origin xyz="0.0 0.0 0.0" rpy="0 0 0" />
      <geometry name="jack2_visual">
        <box size="0.01 ${jack_width} ${jack_height}" />
      </geometry>
    </visual>
    <collision >
      <origin xyz="0.0 0.0 0.0" rpy="0 0 0" />
      <geometry name="jack2_collision_geom">
        <box size="0.01 ${jack_width} ${jack_height}" />
      </geometry>
    </collision>
  </link>
  <gazebo reference="jack2_link">
    <material>PR2/Jack</material>
    <laserRetro>10.0</laserRetro>
    <turnGravityOff>true</turnGravityOff>
    <selfCollide>true</selfCollide>
  </gazebo>

  <joint name="jack3_joint" type="fixed" >
    <parent link="outlet_link" />
    <origin xyz="-0.006 ${-jack_offset_y} ${ jack_offset_z}" rpy="0 0 0" />
    <child link="jack3_link" />
  </joint>
  <link name="jack3_link">
    <inertial >
      <mass value="1.0" />
      <com xyz="0.0 0.0 0.0" /> 
      <inertia  ixx="0.1" ixy="0.0"  ixz="0.0"
                iyy="0.1" iyz="0.0"
                izz="0.1" />
    </inertial>
    <visual >
      <origin xyz="0.0 0.0 0.0" rpy="0 0 0" />
      <geometry name="jack3_visual">
        <box size="0.01 ${jack_width} ${jack_height}" />
      </geometry>
    </visual>
    <collision >
      <origin xyz="0.0 0.0 0.0" rpy="0 0 0" />
      <geometry name="jack3_collision_geom">
        <box size="0.01 ${jack_width} ${jack_height}" />
      </geometry>
    </collision>
  </link>
  <gazebo reference="jack3_link" flag="gazebo">
    <material>PR2/Jack</material>
    <laserRetro>10.0</laserRetro>
    <turnGravityOff>true</turnGravityOff>
    <selfCollide>true</selfCollide>
  </gazebo>

  <joint name="jack4_joint" type="fixed" >
    <parent link="outlet_link" />
    <origin xyz="-0.006 ${ jack_offset_y} ${ jack_offset_z}" rpy="0 0 0" />
    <child link="jack4_link" />
  </joint>
  <link name="jack4_link">
    <inertial >
      <mass value="1.0" />
      <com xyz="0.0 0.0 0.0" /> 
      <inertia  ixx="0.1" ixy="0.0"  ixz="0.0"
                iyy="0.1" iyz="0.0"
                izz="0.1" />
    </inertial>
    <visual >
      <origin xyz="0.0 0.0 0.0" rpy="0 0 0" />
      <geometry name="jack4_visual">
        <box size="0.01 ${jack_width} ${jack_height}" />
      </geometry>
    </visual>
    <collision >
      <origin xyz="0.0 0.0 0.0" rpy="0 0 0" />
      <geometry name="jack4_collision_geom">
        <box size="0.01 ${jack_width} ${jack_height}" />
      </geometry>
    </collision>
  </link>
  <gazebo reference="jack4_link">
    <material>PR2/Jack</material>
    <laserRetro>10.0</laserRetro>
    <turnGravityOff>true</turnGravityOff>
    <selfCollide>true</selfCollide>
  </gazebo>
  -->


  <gazebo>
    <!-- ros_p3d for position groundtruth -->
    <controller:ros_p3d name="p3d_outlet_controller" plugin="libros_p3d.so">
        <alwaysOn>true</alwaysOn>
        <updateRate>100.0</updateRate>
        <bodyName>outlet_link</bodyName>
        <topicName>outlet_pose_ground_truth</topicName>
        <frameName>map</frameName>
        <interface:position name="p3d_outlet_position"/>
    </controller:ros_p3d>
  </gazebo>

</robot>
