<?xml version="1.0"?>
<robot name="pr2"
       xmlns:xi="http://www.w3.org/2001/XInclude"
       xmlns:gazebo="http://playerstage.sourceforge.net/gazebo/xmlschema/#gz"
       xmlns:model="http://playerstage.sourceforge.net/gazebo/xmlschema/#model"
       xmlns:sensor="http://playerstage.sourceforge.net/gazebo/xmlschema/#sensor"
       xmlns:body="http://playerstage.sourceforge.net/gazebo/xmlschema/#body"
       xmlns:geom="http://playerstage.sourceforge.net/gazebo/xmlschema/#geom"
       xmlns:joint="http://playerstage.sourceforge.net/gazebo/xmlschema/#joint"
       xmlns:interface="http://playerstage.sourceforge.net/gazebo/xmlschema/#interface"
       xmlns:rendering="http://playerstage.sourceforge.net/gazebo/xmlschema/#rendering"
       xmlns:renderable="http://playerstage.sourceforge.net/gazebo/xmlschema/#renderable"
       xmlns:controller="http://playerstage.sourceforge.net/gazebo/xmlschema/#controller"
       xmlns:physics="http://playerstage.sourceforge.net/gazebo/xmlschema/#physics">

  <property name="M_PI" value="3.1415926535897931" />

  <property name="plug_x_loc" value="0.25" />
  <property name="plug_y_loc" value="0.0" />
  <property name="plug_z_loc" value="0.282" />
  <property name="plug_x_size" value="0.07" />
  <property name="plug_y_size" value="0.025" />
  <property name="plug_z_size" value="0.03" />

  <!-- joint blocks -->
  <joint name="plug_joint" type="planar" >
    <parent link="world" />
    <origin xyz="${plug_x_loc} ${plug_y_loc} ${plug_z_loc}" rpy="0 0 ${-M_PI/2}" />
    <child link="plug_link" />
  </joint>

  <!-- link blocks -->
  <link name="plug_link">
    <inertial>
      <mass value="0.1" />
      <com xyz="0 0 0.0" />
      <inertia ixx="1.0" ixy="0"  ixz="0"
               iyy="1.0" iyz="0"
               izz="1.0" />
    </inertial> 
    <visual>
      <origin xyz="0 0 0.0" rpy="0 0 0" />
      <geometry name="plug_visual_geom">
        <mesh scale="${plug_x_size} ${plug_y_size} ${plug_z_size}" />
      </geometry>
    </visual> 
    <collision>
      <origin xyz="0 0 0.0" rpy="0 0 0" />
      <geometry name="plug_collision_geom">
        <box size="${plug_x_size} ${plug_y_size} ${plug_z_size}" />
      </geometry>
    </collision>
  </link>

  <gazebo reference="plug_link">
    <material>PR2/Plug</material>
    <mu1>500.0</mu1>
    <mu2>500.0</mu2>
    <kp>100000000.0</kp>
    <kd>1.0</kd>
    <turnGravityOff>true</turnGravityOff>
    <selfCollide>true</selfCollide>
    <dampingFactor>0.5</dampingFactor>
  </gazebo>

  <gazebo>
    <!-- ros_p3d for position groundtruth -->
    <controller:ros_p3d name="p3d_plug_controller" plugin="libros_p3d.so">
        <alwaysOn>true</alwaysOn>
        <updateRate>100.0</updateRate>
        <bodyName>plug_link</bodyName>
        <topicName>plug_pose_ground_truth</topicName>
        <frameName>map</frameName>
        <interface:position name="p3d_plug_position"/>
    </controller:ros_p3d>
    <!-- set plug pose -->
    <controller:ros_sim_iface name="sim_iface_plug_controller" plugin="libros_sim_iface.so">
        <alwaysOn>true</alwaysOn>
        <updateRate>1.0</updateRate>
        <modelName>plug</modelName>
        <topicName>set_plug_pose</topicName>
        <frameName>map</frameName>
        <xyz>0 0 0</xyz>
        <rpy>0 0 0</rpy>
        <vel>0 0 0</vel>
        <angVel>0 0 0</angVel>
        <interface:position name="sim_iface_plug_position"/>
    </controller:ros_sim_iface>
  </gazebo>

</robot>
